Workbook

Sheet Tổng quan
A1: HEBI DASHBOARD - BẢN DỮ LIỆU DEMO
A3: Hidden Environmental Burden Index (Chỉ số Gánh nặng Môi trường Ẩn) | Giá trị thời gian thực chỉ dùng tham khảo; điểm HEBI dùng dữ liệu đại diện.
A5: THÀNH PHỐ MINH HỌA | E5: ĐIỂM HEBI | I5: MỨC RỦI RO / TÁC NHÂN CHÍNH
A6: =CHÍNH!A5 -> Hà Nội | E6: =CHÍNH!Y5 -> 70.927444 | I6: =CHÍNH!Z5 -> Cao
I8: =CHÍNH!AA5 -> PM2.5
A10: PHÂN TÍCH THÀNH PHẦN - HÀ NỘI
A11: Chỉ số | B11: Điểm 0-100
A12: PM2.5 | B12: =CHÍNH!I5 -> 90.888889
A13: Nhiệt độ | B13: =CHÍNH!J5 -> 70
A14: Tiếng ồn | B14: =CHÍNH!K5 -> 83.333333
A15: Mật độ dân số | B15: =CHÍNH!L5 -> 45.684444
A16: Thiếu không gian xanh | B16: =CHÍNH!M5 -> 44.8
A17: Nhóm dễ tổn thương | B17: =CHÍNH!N5 -> 40
A18: Rủi ro thu nhập | B18: =CHÍNH!O5 -> 40.833333
A21: SO SÁNH 5 THÀNH PHỐ
A22: Thành phố | B22: Điểm HEBI | C22: Mức rủi ro | D22: Tác nhân chính | E22: Xếp hạng | F22: PM2.5 hiện tại
A23: =CHÍNH!A5 -> Hà Nội | B23: =CHÍNH!Y5 -> 70.927444 | C23: =CHÍNH!Z5 -> Cao | D23: =CHÍNH!AA5 -> PM2.5 | E23: =CHÍNH!AB5 -> #NAME? | F23: ='Dữ liệu đầu vào'!B6 -> 9
A24: =CHÍNH!A6 -> TP. Hồ Chí Minh | B24: =CHÍNH!Y6 -> 61.998 | C24: =CHÍNH!Z6 -> Cao | D24: =CHÍNH!AA6 -> Tiếng ồn | E24: =CHÍNH!AB6 -> #NAME? | F24: ='Dữ liệu đầu vào'!B7 -> 19
A25: =CHÍNH!A7 -> Đà Nẵng | B25: =CHÍNH!Y7 -> 48.214333 | C25: =CHÍNH!Z7 -> Trung bình | D25: =CHÍNH!AA7 -> Tiếng ồn | E25: =CHÍNH!AB7 -> #NAME? | F25: ='Dữ liệu đầu vào'!B8 -> 7
A26: =CHÍNH!A8 -> Hải Phòng | B26: =CHÍNH!Y8 -> 49.538333 | C26: =CHÍNH!Z8 -> Trung bình | D26: =CHÍNH!AA8 -> Tiếng ồn | E26: =CHÍNH!AB8 -> #NAME? | F26: ='Dữ liệu đầu vào'!B9 -> 14
A27: =CHÍNH!A9 -> Cần Thơ | B27: =CHÍNH!Y9 -> 53.431111 | C27: =CHÍNH!Z9 -> Trung bình | D27: =CHÍNH!AA9 -> PM2.5 | E27: =CHÍNH!AB9 -> #NAME? | F27: ='Dữ liệu đầu vào'!B10 -> 19
A30: CÁCH ĐỌC KẾT QUẢ
A31: Điểm cao hơn nghĩa là gánh nặng môi trường ẩn lớn hơn trong phạm vi mô hình. Bản demo ưu tiên tính minh bạch và hình ảnh hợp lý, không nhằm đưa ra xếp hạng chính thức. Developer chỉ cần thay dữ liệu đầu vào; toàn bộ điểm thành phần, đóng góp và HEBI sẽ tự tính lại.
A37: KHUYẾN NGHỊ TỰ ĐỘNG - HÀ NỘI
A38: =CHÍNH!AC5 -> Ưu tiên giảm phơi nhiễm và phát thải bụi mịn PM2.5.
A40: =CHÍNH!AG5 -> Tác nhân chính: PM2.5. Ưu tiên giảm phơi nhiễm và phát thải bụi mịn PM2.5. Tăng giám sát chất lượng không khí tại trường học, bệnh viện và khu dân cư đông đúc. Phát cảnh báo sức khỏe trong các ngày có nồng độ PM2.5 cao.
A45: Logic đơn giản: Tác nhân chính → tra cứu một dòng trong thư viện → hiển thị khuyến nghị.

Sheet Dữ liệu đầu vào
A1: BỘ DỮ LIỆU ĐẦU VÀO HEBI - BẢN DEMO
A3: Lưu ý: PM2.5 hiện tại và nhiệt độ hôm nay là dữ liệu thời điểm. Điểm HEBI dùng giá trị đại diện để tránh kết quả thay đổi quá mạnh theo từng giờ. Các ô ước tính chỉ phục vụ thiết kế và trực quan hóa.
A5: Thành phố | B5: PM2.5 hiện tại (µg/m³) | C5: Nhiệt độ cao nhất hôm nay (°C) | D5: PM2.5 đại diện dùng chấm điểm (µg/m³) | E5: Nhiệt độ mùa nóng đại diện (°C) | F5: Tiếng ồn đô thị (dB) | G5: Mật độ dân số 2023 (người/km²) | H5: Không gian xanh (m²/người) | I5: Nhóm dễ tổn thương (%) | J5: GRDP/người đại diện (triệu đồng/năm) | K5: Tình trạng dữ liệu | L5: Thời điểm cập nhật | M5: Vĩ độ | N5: Kinh độ
A6: Hà Nội | B6: 9 | C6: 33 | D6: 45.9 | E6: 37 | F6: 75 | G6: 2555.8 | H6: 5.52 | I6: 28 | J6: 151 | K6: 4 chỉ số có nguồn; 3 chỉ số ước tính | L6: 10/07/2026 19:00 | M6: 21.0285 | N6: 105.8542
A7: TP. Hồ Chí Minh | B7: 19 | C7: 32 | D7: 28 | E7: 35 | F7: 78 | G7: 4513.1 | H7: 2.4 | I7: 25 | J7: 170 | K7: 4 chỉ số có nguồn; 3 chỉ số ước tính | L7: 10/07/2026 20:00 | M7: 10.8231 | N7: 106.6297
A8: Đà Nẵng | B8: 7 | C8: 34 | D8: 19.9 | E8: 36 | F8: 70 | G8: 969.2 | H8: 2.4 | I8: 27 | J8: 119 | K8: 3 chỉ số có nguồn; 4 chỉ số ước tính | L8: 10/07/2026 19:00 | M8: 16.0544 | N8: 108.2022
A9: Hải Phòng | B9: 14 | C9: 31 | D9: 25 | E9: 35 | F9: 72 | G9: 1379 | H9: 3.8 | I9: 30 | J9: 173 | K9: 2 chỉ số có nguồn; 5 chỉ số ước tính | L9: 10/07/2026 20:00 | M9: 20.8449 | N9: 106.6881
A10: Cần Thơ | B10: 19 | C10: 34 | D10: 30 | E10: 35.5 | F10: 68 | G10: 874 | H10: 4.5 | I10: 32 | J10: 96 | K10: 2 chỉ số có nguồn; 5 chỉ số ước tính | L10: 10/07/2026 20:00 | M10: 10.0452 | N10: 105.7469

Sheet CHÍNH
A1: BẢNG TÍNH ĐIỂM HEBI - CÔNG THỨC ĐẦY ĐỦ
A4: Thành phố | B4: PM2.5 đại diện | C4: Nhiệt độ đại diện | D4: Tiếng ồn | E4: Mật độ dân số | F4: Không gian xanh | G4: Nhóm dễ tổn thương | H4: GRDP/người | I4: Điểm PM2.5 | J4: Điểm nhiệt | K4: Điểm tiếng ồn | L4: Điểm mật độ | M4: Điểm thiếu không gian xanh | N4: Điểm nhóm dễ tổn thương | O4: Điểm rủi ro thu nhập | P4: Đóng góp PM2.5 | Q4: Đóng góp nhiệt | R4: Đóng góp tiếng ồn | S4: Đóng góp mật độ | T4: Đóng góp không gian xanh | U4: Đóng góp nhóm dễ tổn thương | V4: Đóng góp thu nhập | W4: Điểm phơi nhiễm | X4: Điểm dễ tổn thương | Y4: Điểm HEBI | Z4: Mức rủi ro | AA4: Tác nhân chính | AB4: Xếp hạng | AC4: Khuyến nghị ngắn | AD4: Hành động gợi ý 1 | AE4: Hành động gợi ý 2 | AF4: Giải thích | AG4: Khuyến nghị tổng hợp
A5: ='Dữ liệu đầu vào'!A6 -> Hà Nội | B5: ='Dữ liệu đầu vào'!D6 -> 45.9 | C5: ='Dữ liệu đầu vào'!E6 -> 37 | D5: ='Dữ liệu đầu vào'!F6 -> 75 | E5: ='Dữ liệu đầu vào'!G6 -> 2555.8 | F5: ='Dữ liệu đầu vào'!H6 -> 5.52 | G5: ='Dữ liệu đầu vào'!I6 -> 28 | H5: ='Dữ liệu đầu vào'!J6 -> 151 | I5: =MAX(0,MIN(100,(B5-'Công thức & trọng số'!$E$6)/('Công thức & trọng số'!$F$6-'Công thức & trọng số'!$E$6)*100)) -> 90.888889 | J5: =MAX(0,MIN(100,(C5-'Công thức & trọng số'!$E$7)/('Công thức & trọng số'!$F$7-'Công thức & trọng số'!$E$7)*100)) -> 70 | K5: =MAX(0,MIN(100,(D5-'Công thức & trọng số'!$E$8)/('Công thức & trọng số'!$F$8-'Công thức & trọng số'!$E$8)*100)) -> 83.333333 | L5: =MAX(0,MIN(100,(E5-'Công thức & trọng số'!$E$9)/('Công thức & trọng số'!$F$9-'Công thức & trọng số'!$E$9)*100)) -> 45.684444 | M5: =MAX(0,MIN(100,('Công thức & trọng số'!$F$10-F5)/('Công thức & trọng số'!$F$10-'Công thức & trọng số'!$E$10)*100)) -> 44.8 | N5: =MAX(0,MIN(100,(G5-'Công thức & trọng số'!$E$11)/('Công thức & trọng số'!$F$11-'Công thức & trọng số'!$E$11)*100)) -> 40 | O5: =MAX(0,MIN(100,('Công thức & trọng số'!$F$12-H5)/('Công thức & trọng số'!$F$12-'Công thức & trọng số'!$E$12)*100)) -> 40.833333 | P5: =I5*'Công thức & trọng số'!$G$6 -> 27.266667 | Q5: =J5*'Công thức & trọng số'!$G$7 -> 14 | R5: =K5*'Công thức & trọng số'!$G$8 -> 16.666667 | S5: =L5*'Công thức & trọng số'!$G$9 -> 4.5684444 | T5: =M5*'Công thức & trọng số'!$G$10 -> 3.584 | U5: =N5*'Công thức & trọng số'!$G$11 -> 2.8 | V5: =O5*'Công thức & trọng số'!$G$12 -> 2.0416667 | W5: =SUM(P5:R5)/SUM('Công thức & trọng số'!$G$6:$G$8) -> 82.761905 | X5: =SUM(S5:V5)/SUM('Công thức & trọng số'!$G$9:$G$12) -> 43.313704 | Y5: =SUM(P5:V5) -> 70.927444 | Z5: =IF(Y5<40,"Thấp",IF(Y5<60,"Trung bình",IF(Y5<75,"Cao","Rất cao"))) -> Cao | AA5: =IF(P5=MAX(P5:V5),"PM2.5",IF(Q5=MAX(P5:V5),"Nhiệt độ",IF(R5=MAX(P5:V5),"Tiếng ồn",IF(S5=MAX(P5:V5),"Mật độ dân số",IF(T5=MAX(P5:V5),"Thiếu không gian xanh",IF(U5=MAX(P5:V5),"Nhóm dễ tổn thương","Rủi ro thu nhập")))))) -> PM2.5 | AB5: =_xludf.RANK.EQ(Y5,$Y$5:$Y$9,0) -> #NAME? | AC5: =VLOOKUP(AA5,'Thư viện khuyến nghị'!$A$6:$E$12,2,FALSE) -> Ưu tiên giảm phơi nhiễm và phát thải bụi mịn PM2.5. | AD5: =VLOOKUP(AA5,'Thư viện khuyến nghị'!$A$6:$E$12,3,FALSE) -> Tăng giám sát chất lượng không khí tại trường học, bệnh viện và khu dân cư đông đúc. | AE5: =VLOOKUP(AA5,'Thư viện khuyến nghị'!$A$6:$E$12,4,FALSE) -> Phát cảnh báo sức khỏe trong các ngày có nồng độ PM2.5 cao. | AF5: =VLOOKUP(AA5,'Thư viện khuyến nghị'!$A$6:$E$12,5,FALSE) -> PM2.5 là yếu tố đóng góp lớn nhất vào gánh nặng môi trường của thành phố. | AG5: ="Tác nhân chính: "&AA5&". "&AC5&" "&AD5&" "&AE5 -> Tác nhân chính: PM2.5. Ưu tiên giảm phơi nhiễm và phát thải bụi mịn PM2.5. Tăng giám sát chất lượng không khí tại trường học, bệnh viện và khu dân cư đông đúc. Phát cảnh báo sức khỏe trong các ngày có nồng độ PM2.5 cao.
A6: ='Dữ liệu đầu vào'!A7 -> TP. Hồ Chí Minh | B6: ='Dữ liệu đầu vào'!D7 -> 28 | C6: ='Dữ liệu đầu vào'!E7 -> 35 | D6: ='Dữ liệu đầu vào'!F7 -> 78 | E6: ='Dữ liệu đầu vào'!G7 -> 4513.1 | F6: ='Dữ liệu đầu vào'!H7 -> 2.4 | G6: ='Dữ liệu đầu vào'!I7 -> 25 | H6: ='Dữ liệu đầu vào'!J7 -> 170 | I6: =MAX(0,MIN(100,(B6-'Công thức & trọng số'!$E$6)/('Công thức & trọng số'!$F$6-'Công thức & trọng số'!$E$6)*100)) -> 51.111111 | J6: =MAX(0,MIN(100,(C6-'Công thức & trọng số'!$E$7)/('Công thức & trọng số'!$F$7-'Công thức & trọng số'!$E$7)*100)) -> 50 | K6: =MAX(0,MIN(100,(D6-'Công thức & trọng số'!$E$8)/('Công thức & trọng số'!$F$8-'Công thức & trọng số'!$E$8)*100)) -> 93.333333 | L6: =MAX(0,MIN(100,(E6-'Công thức & trọng số'!$E$9)/('Công thức & trọng số'!$F$9-'Công thức & trọng số'!$E$9)*100)) -> 89.18 | M6: =MAX(0,MIN(100,('Công thức & trọng số'!$F$10-F6)/('Công thức & trọng số'!$F$10-'Công thức & trọng số'!$E$10)*100)) -> 76 | N6: =MAX(0,MIN(100,(G6-'Công thức & trọng số'!$E$11)/('Công thức & trọng số'!$F$11-'Công thức & trọng số'!$E$11)*100)) -> 25 | O6: =MAX(0,MIN(100,('Công thức & trọng số'!$F$12-H6)/('Công thức & trọng số'!$F$12-'Công thức & trọng số'!$E$12)*100)) -> 25 | P6: =I6*'Công thức & trọng số'!$G$6 -> 15.333333 | Q6: =J6*'Công thức & trọng số'!$G$7 -> 10 | R6: =K6*'Công thức & trọng số'!$G$8 -> 18.666667 | S6: =L6*'Công thức & trọng số'!$G$9 -> 8.918 | T6: =M6*'Công thức & trọng số'!$G$10 -> 6.08 | U6: =N6*'Công thức & trọng số'!$G$11 -> 1.75 | V6: =O6*'Công thức & trọng số'!$G$12 -> 1.25 | W6: =SUM(P6:R6)/SUM('Công thức & trọng số'!$G$6:$G$8) -> 62.857143 | X6: =SUM(S6:V6)/SUM('Công thức & trọng số'!$G$9:$G$12) -> 59.993333 | Y6: =SUM(P6:V6) -> 61.998 | Z6: =IF(Y6<40,"Thấp",IF(Y6<60,"Trung bình",IF(Y6<75,"Cao","Rất cao"))) -> Cao | AA6: =IF(P6=MAX(P6:V6),"PM2.5",IF(Q6=MAX(P6:V6),"Nhiệt độ",IF(R6=MAX(P6:V6),"Tiếng ồn",IF(S6=MAX(P6:V6),"Mật độ dân số",IF(T6=MAX(P6:V6),"Thiếu không gian xanh",IF(U6=MAX(P6:V6),"Nhóm dễ tổn thương","Rủi ro thu nhập")))))) -> Tiếng ồn | AB6: =_xludf.RANK.EQ(Y6,$Y$5:$Y$9,0) -> #NAME? | AC6: =VLOOKUP(AA6,'Thư viện khuyến nghị'!$A$6:$E$12,2,FALSE) -> Ưu tiên kiểm soát tiếng ồn giao thông và xây dựng. | AD6: =VLOOKUP(AA6,'Thư viện khuyến nghị'!$A$6:$E$12,3,FALSE) -> Theo dõi tiếng ồn tại các trục đường lớn, trường học và bệnh viện. | AE6: =VLOOKUP(AA6,'Thư viện khuyến nghị'!$A$6:$E$12,4,FALSE) -> Hạn chế còi xe và hoạt động gây ồn tại các khung giờ nhạy cảm. | AF6: =VLOOKUP(AA6,'Thư viện khuyến nghị'!$A$6:$E$12,5,FALSE) -> Tiếng ồn là yếu tố đóng góp lớn nhất vào gánh nặng môi trường của thành phố. | AG6: ="Tác nhân chính: "&AA6&". "&AC6&" "&AD6&" "&AE6 -> Tác nhân chính: Tiếng ồn. Ưu tiên kiểm soát tiếng ồn giao thông và xây dựng. Theo dõi tiếng ồn tại các trục đường lớn, trường học và bệnh viện. Hạn chế còi xe và hoạt động gây ồn tại các khung giờ nhạy cảm.
A7: ='Dữ liệu đầu vào'!A8 -> Đà Nẵng | B7: ='Dữ liệu đầu vào'!D8 -> 19.9 | C7: ='Dữ liệu đầu vào'!E8 -> 36 | D7: ='Dữ liệu đầu vào'!F8 -> 70 | E7: ='Dữ liệu đầu vào'!G8 -> 969.2 | F7: ='Dữ liệu đầu vào'!H8 -> 2.4 | G7: ='Dữ liệu đầu vào'!I8 -> 27 | H7: ='Dữ liệu đầu vào'!J8 -> 119 | I7: =MAX(0,MIN(100,(B7-'Công thức & trọng số'!$E$6)/('Công thức & trọng số'!$F$6-'Công thức & trọng số'!$E$6)*100)) -> 33.111111 | J7: =MAX(0,MIN(100,(C7-'Công thức & trọng số'!$E$7)/('Công thức & trọng số'!$F$7-'Công thức & trọng số'!$E$7)*100)) -> 60 | K7: =MAX(0,MIN(100,(D7-'Công thức & trọng số'!$E$8)/('Công thức & trọng số'!$F$8-'Công thức & trọng số'!$E$8)*100)) -> 66.666667 | L7: =MAX(0,MIN(100,(E7-'Công thức & trọng số'!$E$9)/('Công thức & trọng số'!$F$9-'Công thức & trọng số'!$E$9)*100)) -> 10.426667 | M7: =MAX(0,MIN(100,('Công thức & trọng số'!$F$10-F7)/('Công thức & trọng số'!$F$10-'Công thức & trọng số'!$E$10)*100)) -> 76 | N7: =MAX(0,MIN(100,(G7-'Công thức & trọng số'!$E$11)/('Công thức & trọng số'!$F$11-'Công thức & trọng số'!$E$11)*100)) -> 35 | O7: =MAX(0,MIN(100,('Công thức & trọng số'!$F$12-H7)/('Công thức & trọng số'!$F$12-'Công thức & trọng số'!$E$12)*100)) -> 67.5 | P7: =I7*'Công thức & trọng số'!$G$6 -> 9.9333333 | Q7: =J7*'Công thức & trọng số'!$G$7 -> 12 | R7: =K7*'Công thức & trọng số'!$G$8 -> 13.333333 | S7: =L7*'Công thức & trọng số'!$G$9 -> 1.0426667 | T7: =M7*'Công thức & trọng số'!$G$10 -> 6.08 | U7: =N7*'Công thức & trọng số'!$G$11 -> 2.45 | V7: =O7*'Công thức & trọng số'!$G$12 -> 3.375 | W7: =SUM(P7:R7)/SUM('Công thức & trọng số'!$G$6:$G$8) -> 50.380952 | X7: =SUM(S7:V7)/SUM('Công thức & trọng số'!$G$9:$G$12) -> 43.158889 | Y7: =SUM(P7:V7) -> 48.214333 | Z7: =IF(Y7<40,"Thấp",IF(Y7<60,"Trung bình",IF(Y7<75,"Cao","Rất cao"))) -> Trung bình | AA7: =IF(P7=MAX(P7:V7),"PM2.5",IF(Q7=MAX(P7:V7),"Nhiệt độ",IF(R7=MAX(P7:V7),"Tiếng ồn",IF(S7=MAX(P7:V7),"Mật độ dân số",IF(T7=MAX(P7:V7),"Thiếu không gian xanh",IF(U7=MAX(P7:V7),"Nhóm dễ tổn thương","Rủi ro thu nhập")))))) -> Tiếng ồn | AB7: =_xludf.RANK.EQ(Y7,$Y$5:$Y$9,0) -> #NAME? | AC7: =VLOOKUP(AA7,'Thư viện khuyến nghị'!$A$6:$E$12,2,FALSE) -> Ưu tiên kiểm soát tiếng ồn giao thông và xây dựng. | AD7: =VLOOKUP(AA7,'Thư viện khuyến nghị'!$A$6:$E$12,3,FALSE) -> Theo dõi tiếng ồn tại các trục đường lớn, trường học và bệnh viện. | AE7: =VLOOKUP(AA7,'Thư viện khuyến nghị'!$A$6:$E$12,4,FALSE) -> Hạn chế còi xe và hoạt động gây ồn tại các khung giờ nhạy cảm. | AF7: =VLOOKUP(AA7,'Thư viện khuyến nghị'!$A$6:$E$12,5,FALSE) -> Tiếng ồn là yếu tố đóng góp lớn nhất vào gánh nặng môi trường của thành phố. | AG7: ="Tác nhân chính: "&AA7&". "&AC7&" "&AD7&" "&AE7 -> Tác nhân chính: Tiếng ồn. Ưu tiên kiểm soát tiếng ồn giao thông và xây dựng. Theo dõi tiếng ồn tại các trục đường lớn, trường học và bệnh viện. Hạn chế còi xe và hoạt động gây ồn tại các khung giờ nhạy cảm.
A8: ='Dữ liệu đầu vào'!A9 -> Hải Phòng | B8: ='Dữ liệu đầu vào'!D9 -> 25 | C8: ='Dữ liệu đầu vào'!E9 -> 35 | D8: ='Dữ liệu đầu vào'!F9 -> 72 | E8: ='Dữ liệu đầu vào'!G9 -> 1379 | F8: ='Dữ liệu đầu vào'!H9 -> 3.8 | G8: ='Dữ liệu đầu vào'!I9 -> 30 | H8: ='Dữ liệu đầu vào'!J9 -> 173 | I8: =MAX(0,MIN(100,(B8-'Công thức & trọng số'!$E$6)/('Công thức & trọng số'!$F$6-'Công thức & trọng số'!$E$6)*100)) -> 44.444444 | J8: =MAX(0,MIN(100,(C8-'Công thức & trọng số'!$E$7)/('Công thức & trọng số'!$F$7-'Công thức & trọng số'!$E$7)*100)) -> 50 | K8: =MAX(0,MIN(100,(D8-'Công thức & trọng số'!$E$8)/('Công thức & trọng số'!$F$8-'Công thức & trọng số'!$E$8)*100)) -> 73.333333 | L8: =MAX(0,MIN(100,(E8-'Công thức & trọng số'!$E$9)/('Công thức & trọng số'!$F$9-'Công thức & trọng số'!$E$9)*100)) -> 19.533333 | M8: =MAX(0,MIN(100,('Công thức & trọng số'!$F$10-F8)/('Công thức & trọng số'!$F$10-'Công thức & trọng số'!$E$10)*100)) -> 62 | N8: =MAX(0,MIN(100,(G8-'Công thức & trọng số'!$E$11)/('Công thức & trọng số'!$F$11-'Công thức & trọng số'!$E$11)*100)) -> 50 | O8: =MAX(0,MIN(100,('Công thức & trọng số'!$F$12-H8)/('Công thức & trọng số'!$F$12-'Công thức & trọng số'!$E$12)*100)) -> 22.5 | P8: =I8*'Công thức & trọng số'!$G$6 -> 13.333333 | Q8: =J8*'Công thức & trọng số'!$G$7 -> 10 | R8: =K8*'Công thức & trọng số'!$G$8 -> 14.666667 | S8: =L8*'Công thức & trọng số'!$G$9 -> 1.9533333 | T8: =M8*'Công thức & trọng số'!$G$10 -> 4.96 | U8: =N8*'Công thức & trọng số'!$G$11 -> 3.5 | V8: =O8*'Công thức & trọng số'!$G$12 -> 1.125 | W8: =SUM(P8:R8)/SUM('Công thức & trọng số'!$G$6:$G$8) -> 54.285714 | X8: =SUM(S8:V8)/SUM('Công thức & trọng số'!$G$9:$G$12) -> 38.461111 | Y8: =SUM(P8:V8) -> 49.538333 | Z8: =IF(Y8<40,"Thấp",IF(Y8<60,"Trung bình",IF(Y8<75,"Cao","Rất cao"))) -> Trung bình | AA8: =IF(P8=MAX(P8:V8),"PM2.5",IF(Q8=MAX(P8:V8),"Nhiệt độ",IF(R8=MAX(P8:V8),"Tiếng ồn",IF(S8=MAX(P8:V8),"Mật độ dân số",IF(T8=MAX(P8:V8),"Thiếu không gian xanh",IF(U8=MAX(P8:V8),"Nhóm dễ tổn thương","Rủi ro thu nhập")))))) -> Tiếng ồn | AB8: =_xludf.RANK.EQ(Y8,$Y$5:$Y$9,0) -> #NAME? | AC8: =VLOOKUP(AA8,'Thư viện khuyến nghị'!$A$6:$E$12,2,FALSE) -> Ưu tiên kiểm soát tiếng ồn giao thông và xây dựng. | AD8: =VLOOKUP(AA8,'Thư viện khuyến nghị'!$A$6:$E$12,3,FALSE) -> Theo dõi tiếng ồn tại các trục đường lớn, trường học và bệnh viện. | AE8: =VLOOKUP(AA8,'Thư viện khuyến nghị'!$A$6:$E$12,4,FALSE) -> Hạn chế còi xe và hoạt động gây ồn tại các khung giờ nhạy cảm. | AF8: =VLOOKUP(AA8,'Thư viện khuyến nghị'!$A$6:$E$12,5,FALSE) -> Tiếng ồn là yếu tố đóng góp lớn nhất vào gánh nặng môi trường của thành phố. | AG8: ="Tác nhân chính: "&AA8&". "&AC8&" "&AD8&" "&AE8 -> Tác nhân chính: Tiếng ồn. Ưu tiên kiểm soát tiếng ồn giao thông và xây dựng. Theo dõi tiếng ồn tại các trục đường lớn, trường học và bệnh viện. Hạn chế còi xe và hoạt động gây ồn tại các khung giờ nhạy cảm.
A9: ='Dữ liệu đầu vào'!A10 -> Cần Thơ | B9: ='Dữ liệu đầu vào'!D10 -> 30 | C9: ='Dữ liệu đầu vào'!E10 -> 35.5 | D9: ='Dữ liệu đầu vào'!F10 -> 68 | E9: ='Dữ liệu đầu vào'!G10 -> 874 | F9: ='Dữ liệu đầu vào'!H10 -> 4.5 | G9: ='Dữ liệu đầu vào'!I10 -> 32 | H9: ='Dữ liệu đầu vào'!J10 -> 96 | I9: =MAX(0,MIN(100,(B9-'Công thức & trọng số'!$E$6)/('Công thức & trọng số'!$F$6-'Công thức & trọng số'!$E$6)*100)) -> 55.555556 | J9: =MAX(0,MIN(100,(C9-'Công thức & trọng số'!$E$7)/('Công thức & trọng số'!$F$7-'Công thức & trọng số'!$E$7)*100)) -> 55 | K9: =MAX(0,MIN(100,(D9-'Công thức & trọng số'!$E$8)/('Công thức & trọng số'!$F$8-'Công thức & trọng số'!$E$8)*100)) -> 60 | L9: =MAX(0,MIN(100,(E9-'Công thức & trọng số'!$E$9)/('Công thức & trọng số'!$F$9-'Công thức & trọng số'!$E$9)*100)) -> 8.3111111 | M9: =MAX(0,MIN(100,('Công thức & trọng số'!$F$10-F9)/('Công thức & trọng số'!$F$10-'Công thức & trọng số'!$E$10)*100)) -> 55 | N9: =MAX(0,MIN(100,(G9-'Công thức & trọng số'!$E$11)/('Công thức & trọng số'!$F$11-'Công thức & trọng số'!$E$11)*100)) -> 60 | O9: =MAX(0,MIN(100,('Công thức & trọng số'!$F$12-H9)/('Công thức & trọng số'!$F$12-'Công thức & trọng số'!$E$12)*100)) -> 86.666667 | P9: =I9*'Công thức & trọng số'!$G$6 -> 16.666667 | Q9: =J9*'Công thức & trọng số'!$G$7 -> 11 | R9: =K9*'Công thức & trọng số'!$G$8 -> 12 | S9: =L9*'Công thức & trọng số'!$G$9 -> 0.83111111 | T9: =M9*'Công thức & trọng số'!$G$10 -> 4.4 | U9: =N9*'Công thức & trọng số'!$G$11 -> 4.2 | V9: =O9*'Công thức & trọng số'!$G$12 -> 4.3333333 | W9: =SUM(P9:R9)/SUM('Công thức & trọng số'!$G$6:$G$8) -> 56.666667 | X9: =SUM(S9:V9)/SUM('Công thức & trọng số'!$G$9:$G$12) -> 45.881481 | Y9: =SUM(P9:V9) -> 53.431111 | Z9: =IF(Y9<40,"Thấp",IF(Y9<60,"Trung bình",IF(Y9<75,"Cao","Rất cao"))) -> Trung bình | AA9: =IF(P9=MAX(P9:V9),"PM2.5",IF(Q9=MAX(P9:V9),"Nhiệt độ",IF(R9=MAX(P9:V9),"Tiếng ồn",IF(S9=MAX(P9:V9),"Mật độ dân số",IF(T9=MAX(P9:V9),"Thiếu không gian xanh",IF(U9=MAX(P9:V9),"Nhóm dễ tổn thương","Rủi ro thu nhập")))))) -> PM2.5 | AB9: =_xludf.RANK.EQ(Y9,$Y$5:$Y$9,0) -> #NAME? | AC9: =VLOOKUP(AA9,'Thư viện khuyến nghị'!$A$6:$E$12,2,FALSE) -> Ưu tiên giảm phơi nhiễm và phát thải bụi mịn PM2.5. | AD9: =VLOOKUP(AA9,'Thư viện khuyến nghị'!$A$6:$E$12,3,FALSE) -> Tăng giám sát chất lượng không khí tại trường học, bệnh viện và khu dân cư đông đúc. | AE9: =VLOOKUP(AA9,'Thư viện khuyến nghị'!$A$6:$E$12,4,FALSE) -> Phát cảnh báo sức khỏe trong các ngày có nồng độ PM2.5 cao. | AF9: =VLOOKUP(AA9,'Thư viện khuyến nghị'!$A$6:$E$12,5,FALSE) -> PM2.5 là yếu tố đóng góp lớn nhất vào gánh nặng môi trường của thành phố. | AG9: ="Tác nhân chính: "&AA9&". "&AC9&" "&AD9&" "&AE9 -> Tác nhân chính: PM2.5. Ưu tiên giảm phơi nhiễm và phát thải bụi mịn PM2.5. Tăng giám sát chất lượng không khí tại trường học, bệnh viện và khu dân cư đông đúc. Phát cảnh báo sức khỏe trong các ngày có nồng độ PM2.5 cao.

Sheet Công thức & trọng số
A1: CÔNG THỨC TÍNH CHỈ SỐ HEBI
A3: Mỗi chỉ số được chuẩn hóa về thang 0-100, sau đó nhân với trọng số
A5: Chỉ số | B5: Nhóm | C5: Đơn vị | D5: Chiều rủi ro | E5: Mốc thấp | F5: Mốc cao | G5: Trọng số | H5: Công thức chuẩn hóa | I5: Giải thích lựa chọn
A6: PM2.5 | B6: Phơi nhiễm môi trường | C6: µg/m³ | D6: Càng cao càng xấu | E6: 5 | F6: 50 | G6: 0.3 | H6: MAX(0; MIN(100; (X - 5) / (50 - 5) × 100)) | I6: Mốc 5 tham chiếu hướng dẫn WHO; mốc 50 dùng để tạo dải điểm demo.
A7: Nhiệt độ mùa nóng | B7: Phơi nhiễm môi trường | C7: °C | D7: Càng cao càng xấu | E7: 30 | F7: 40 | G7: 0.2 | H7: MAX(0; MIN(100; (X - 30) / (40 - 30) × 100)) | I7: Mốc nội bộ để phân biệt mức nóng đô thị trong bản mẫu.
A8: Tiếng ồn đô thị | B8: Phơi nhiễm môi trường | C8: dB | D8: Càng cao càng xấu | E8: 50 | F8: 80 | G8: 0.2 | H8: MAX(0; MIN(100; (X - 50) / (80 - 50) × 100)) | I8: Dựa trên khoảng tiếng ồn giao thông đô thị được ghi nhận trong nghiên cứu Việt Nam.
A9: Mật độ dân số | B9: Dễ tổn thương xã hội | C9: người/km² | D9: Càng cao càng xấu | E9: 500 | F9: 5000 | G9: 0.1 | H9: MAX(0; MIN(100; (X - 500) / (5000 - 500) × 100)) | I9: Dải thiết kế bao phủ từ đô thị mật độ thấp đến rất cao trong nhóm 5 thành phố.
A10: Không gian xanh | B10: Dễ tổn thương xã hội | C10: m²/người | D10: Càng cao càng tốt | E10: 0 | F10: 10 | G10: 0.08 | H10: MAX(0; MIN(100; (10 - X) / (10 - 0) × 100)) | I10: Đảo chiều: ít không gian xanh tạo điểm rủi ro cao hơn.
A11: Nhóm dễ tổn thương | B11: Dễ tổn thương xã hội | C11: % dân số | D11: Càng cao càng xấu | E11: 20 | F11: 40 | G11: 0.07 | H11: MAX(0; MIN(100; (X - 20) / (40 - 20) × 100)) | I11: Gồm trẻ em và người cao tuổi; hiện là ước tính cho bản demo.
A12: GRDP/người | B12: Dễ tổn thương xã hội | C12: triệu đồng/năm | D12: Càng cao càng tốt | E12: 80 | F12: 200 | G12: 0.05 | H12: MAX(0; MIN(100; (200 - X) / (200 - 80) × 100)) | I12: Đảo chiều: thu nhập đại diện cao hơn được xem là khả năng thích ứng tốt hơn.
A13: Tổng trọng số | G13: =SUM(G6:G12) -> 1 | H13: HEBI = tổng (Điểm chuẩn hóa × Trọng số)
A15: PHÂN LOẠI MỨC RỦI RO
A16: Khoảng điểm | B16: Mức rủi ro | C16: Màu hiển thị
A17: 0 - 39,9 | B17: Thấp | C17: Xanh
A18: 40 - 59,9 | B18: Trung bình | C18: Vàng
A19: 60 - 74,9 | B19: Cao | C19: Cam
A20: 75 - 100 | B20: Rất cao | C20: Đỏ

Sheet Nguồn dữ liệu & API
A1: NGUỒN DỮ LIỆU, GIẢ ĐỊNH VÀ GỢI Ý API
A3: Dữ liệu có nhãn “Ước tính phục vụ demo” được chọn để tạo hình ảnh trực quan hợp lý. Developer có thể thay giá trị mà không cần đổi công thức.
A5: STT | B5: Thành phố | C5: Chỉ số | D5: Giá trị dùng chấm điểm | E5: Đơn vị | F5: Loại dữ liệu | G5: Thời kỳ / tham chiếu | H5: Giá trị thời gian thực tham khảo | I5: Ghi chú phương pháp | J5: URL nguồn
A6: 1 | B6: Hà Nội | C6: PM2.5 | D6: 45.9 | E6: µg/m³ | F6: Có nguồn + ước tính đại diện | G6: 2025 / đại diện | H6: 9 | I6: PM2.5 hiện tại: 9.0 µg/m³. Giá trị dùng chấm điểm là mức đại diện, tránh biến động theo từng giờ. Hà Nội dùng mức trung bình 2025 được IQAir công bố. | J6: https://www.iqair.com/vi/air-quality/vietnam/ha-noi/hanoi
A7: 2 | B7: Hà Nội | C7: Nhiệt độ mùa nóng | D7: 37 | E7: °C | F7: Ước tính từ dữ liệu ngày hiện tại | G7: Mùa nóng đại diện | H7: 33 | I7: Nhiệt độ cao nhất hôm nay dùng làm tham khảo; mức chấm điểm được nâng về giá trị mùa nóng điển hình. | J7: https://www.iqair.com/vi/air-quality/vietnam/ha-noi/hanoi
A8: 3 | B8: Hà Nội | C8: Tiếng ồn đô thị | D8: 75 | E8: dB | F8: Giá trị nghiên cứu tham khảo | G8: Đại diện ban ngày | I8: Hà Nội và TP.HCM tham chiếu nghiên cứu tiếng ồn giao thông; thành phố khác ước tính theo quy mô giao thông. | J8: https://www.sciencedirect.com/science/article/abs/pii/S0003682X09002710
A9: 4 | B9: Hà Nội | C9: Mật độ dân số | D9: 2555.8 | E9: người/km² | F9: Số liệu thống kê | G9: 2023 | I9: CEIC dẫn nguồn Tổng cục Thống kê / National Statistics Office. | J9: https://www.ceicdata.com/en/vietnam/population-density-by-provinces/population-density-rr-ha-noi
A10: 5 | B10: Hà Nội | C10: Không gian xanh | D10: 5.52 | E10: m²/người | F10: Dữ liệu báo cáo | G10: 2025 / đại diện | I10: Hà Nội, TP.HCM và Đà Nẵng có số liệu công bố; Hải Phòng và Cần Thơ ước tính theo quy mô đô thị. | J10: https://vietnamnews.vn/society/1692989/urban-greenery-falls-short-despite-tree-planting-effort.html
A11: 6 | B11: Hà Nội | C11: Nhóm dễ tổn thương | D11: 28 | E11: % | F11: Ước tính phục vụ demo | G11: Đại diện cơ cấu dân số | I11: Ước tính tổng tỷ lệ trẻ em và người cao tuổi; cần thay bằng dữ liệu điều tra chi tiết khi có. | J11: https://vietnam.unfpa.org/sites/default/files/pub-pdf/Results%20-%202019%20Population%20and%20Housing%20Census_full.pdf
A12: 7 | B12: Hà Nội | C12: GRDP/người đại diện | D12: 151 | E12: triệu đồng/năm | F12: Ước tính phục vụ demo | G12: 2023-2024 đại diện | I12: Dùng làm proxy cho năng lực thích ứng kinh tế; không dùng như số liệu báo cáo chính thức. | J12: https://www.nso.gov.vn/wp-content/uploads/2025/06/NGTK-Cuc-TK-2024_BQ_PDF.pdf
A13: 8 | B13: TP. Hồ Chí Minh | C13: PM2.5 | D13: 28 | E13: µg/m³ | F13: Có nguồn + ước tính đại diện | G13: 2025 / đại diện | H13: 19 | I13: PM2.5 hiện tại: 19.0 µg/m³. Giá trị dùng chấm điểm là mức đại diện, tránh biến động theo từng giờ. Giá trị đại diện được ước tính từ dữ liệu trang và vị thế tương đối giữa các thành phố. | J13: https://www.iqair.com/air-quality/vietnam/ho-chi-minh-city/ho-chi-minh-city
A14: 9 | B14: TP. Hồ Chí Minh | C14: Nhiệt độ mùa nóng | D14: 35 | E14: °C | F14: Ước tính từ dữ liệu ngày hiện tại | G14: Mùa nóng đại diện | H14: 32 | I14: Nhiệt độ cao nhất hôm nay dùng làm tham khảo; mức chấm điểm được nâng về giá trị mùa nóng điển hình. | J14: https://www.iqair.com/air-quality/vietnam/ho-chi-minh-city/ho-chi-minh-city
A15: 10 | B15: TP. Hồ Chí Minh | C15: Tiếng ồn đô thị | D15: 78 | E15: dB | F15: Giá trị nghiên cứu tham khảo | G15: Đại diện ban ngày | I15: Hà Nội và TP.HCM tham chiếu nghiên cứu tiếng ồn giao thông; thành phố khác ước tính theo quy mô giao thông. | J15: https://www.sciencedirect.com/science/article/abs/pii/S0003682X09002710
A16: 11 | B16: TP. Hồ Chí Minh | C16: Mật độ dân số | D16: 4513.1 | E16: người/km² | F16: Số liệu thống kê | G16: 2023 | I16: CEIC dẫn nguồn Tổng cục Thống kê / National Statistics Office. | J16: https://www.ceicdata.com/en/vietnam/population-density-by-provinces/population-density-se-ho-chi-minh-city
A17: 12 | B17: TP. Hồ Chí Minh | C17: Không gian xanh | D17: 2.4 | E17: m²/người | F17: Dữ liệu báo cáo | G17: 2025 / đại diện | I17: Hà Nội, TP.HCM và Đà Nẵng có số liệu công bố; Hải Phòng và Cần Thơ ước tính theo quy mô đô thị. | J17: https://vietnamnews.vn/society/1692989/urban-greenery-falls-short-despite-tree-planting-effort.html
A18: 13 | B18: TP. Hồ Chí Minh | C18: Nhóm dễ tổn thương | D18: 25 | E18: % | F18: Ước tính phục vụ demo | G18: Đại diện cơ cấu dân số | I18: Ước tính tổng tỷ lệ trẻ em và người cao tuổi; cần thay bằng dữ liệu điều tra chi tiết khi có. | J18: https://vietnam.unfpa.org/sites/default/files/pub-pdf/Results%20-%202019%20Population%20and%20Housing%20Census_full.pdf
A19: 14 | B19: TP. Hồ Chí Minh | C19: GRDP/người đại diện | D19: 170 | E19: triệu đồng/năm | F19: Ước tính phục vụ demo | G19: 2023-2024 đại diện | I19: Dùng làm proxy cho năng lực thích ứng kinh tế; không dùng như số liệu báo cáo chính thức. | J19: https://www.nso.gov.vn/wp-content/uploads/2025/06/NGTK-Cuc-TK-2024_BQ_PDF.pdf
A20: 15 | B20: Đà Nẵng | C20: PM2.5 | D20: 19.9 | E20: µg/m³ | F20: Có nguồn + ước tính đại diện | G20: 2025 / đại diện | H20: 7 | I20: PM2.5 hiện tại: 7.0 µg/m³. Giá trị dùng chấm điểm là mức đại diện, tránh biến động theo từng giờ. Đà Nẵng dùng mức xấp xỉ dài hạn trên trang IQAir. | J20: https://www.iqair.com/air-quality/vietnam/da-nang-city/da-nang
A21: 16 | B21: Đà Nẵng | C21: Nhiệt độ mùa nóng | D21: 36 | E21: °C | F21: Ước tính từ dữ liệu ngày hiện tại | G21: Mùa nóng đại diện | H21: 34 | I21: Nhiệt độ cao nhất hôm nay dùng làm tham khảo; mức chấm điểm được nâng về giá trị mùa nóng điển hình. | J21: https://www.iqair.com/air-quality/vietnam/da-nang-city/da-nang
A22: 17 | B22: Đà Nẵng | C22: Tiếng ồn đô thị | D22: 70 | E22: dB | F22: Ước tính phục vụ demo | G22: Đại diện ban ngày | I22: Hà Nội và TP.HCM tham chiếu nghiên cứu tiếng ồn giao thông; thành phố khác ước tính theo quy mô giao thông. | J22: https://www.sciencedirect.com/science/article/abs/pii/S0003682X09002710
A23: 18 | B23: Đà Nẵng | C23: Mật độ dân số | D23: 969.2 | E23: người/km² | F23: Số liệu thống kê | G23: 2023 | I23: CEIC dẫn nguồn Tổng cục Thống kê / National Statistics Office. | J23: https://www.ceicdata.com/en/vietnam/population-density-by-provinces/population-density-nc-da-nang
A24: 19 | B24: Đà Nẵng | C24: Không gian xanh | D24: 2.4 | E24: m²/người | F24: Dữ liệu báo cáo | G24: 2025 / đại diện | I24: Hà Nội, TP.HCM và Đà Nẵng có số liệu công bố; Hải Phòng và Cần Thơ ước tính theo quy mô đô thị. | J24: https://vietnamnews.vn/society/1692989/urban-greenery-falls-short-despite-tree-planting-effort.html
A25: 20 | B25: Đà Nẵng | C25: Nhóm dễ tổn thương | D25: 27 | E25: % | F25: Ước tính phục vụ demo | G25: Đại diện cơ cấu dân số | I25: Ước tính tổng tỷ lệ trẻ em và người cao tuổi; cần thay bằng dữ liệu điều tra chi tiết khi có. | J25: https://vietnam.unfpa.org/sites/default/files/pub-pdf/Results%20-%202019%20Population%20and%20Housing%20Census_full.pdf
A26: 21 | B26: Đà Nẵng | C26: GRDP/người đại diện | D26: 119 | E26: triệu đồng/năm | F26: Ước tính phục vụ demo | G26: 2023-2024 đại diện | I26: Dùng làm proxy cho năng lực thích ứng kinh tế; không dùng như số liệu báo cáo chính thức. | J26: https://www.nso.gov.vn/wp-content/uploads/2025/06/NGTK-Cuc-TK-2024_BQ_PDF.pdf
A27: 22 | B27: Hải Phòng | C27: PM2.5 | D27: 25 | E27: µg/m³ | F27: Có nguồn + ước tính đại diện | G27: 2025 / đại diện | H27: 14 | I27: PM2.5 hiện tại: 14.0 µg/m³. Giá trị dùng chấm điểm là mức đại diện, tránh biến động theo từng giờ. Giá trị đại diện được ước tính từ dữ liệu trang và vị thế tương đối giữa các thành phố. | J27: https://www.iqair.com/vi/air-quality/vietnam/hai-phong-city/haiphong
A28: 23 | B28: Hải Phòng | C28: Nhiệt độ mùa nóng | D28: 35 | E28: °C | F28: Ước tính từ dữ liệu ngày hiện tại | G28: Mùa nóng đại diện | H28: 31 | I28: Nhiệt độ cao nhất hôm nay dùng làm tham khảo; mức chấm điểm được nâng về giá trị mùa nóng điển hình. | J28: https://www.iqair.com/vi/air-quality/vietnam/hai-phong-city/haiphong
A29: 24 | B29: Hải Phòng | C29: Tiếng ồn đô thị | D29: 72 | E29: dB | F29: Ước tính phục vụ demo | G29: Đại diện ban ngày | I29: Hà Nội và TP.HCM tham chiếu nghiên cứu tiếng ồn giao thông; thành phố khác ước tính theo quy mô giao thông. | J29: https://www.sciencedirect.com/science/article/abs/pii/S0003682X09002710
A30: 25 | B30: Hải Phòng | C30: Mật độ dân số | D30: 1379 | E30: người/km² | F30: Số liệu thống kê | G30: 2023 | I30: CEIC dẫn nguồn Tổng cục Thống kê / National Statistics Office. | J30: https://www.ceicdata.com/en/vietnam/population-density-by-provinces/population-density-rr-hai-phong
A31: 26 | B31: Hải Phòng | C31: Không gian xanh | D31: 3.8 | E31: m²/người | F31: Ước tính phục vụ demo | G31: 2025 / đại diện | I31: Hà Nội, TP.HCM và Đà Nẵng có số liệu công bố; Hải Phòng và Cần Thơ ước tính theo quy mô đô thị. | J31: https://vietnamnews.vn/society/1692989/urban-greenery-falls-short-despite-tree-planting-effort.html
A32: 27 | B32: Hải Phòng | C32: Nhóm dễ tổn thương | D32: 30 | E32: % | F32: Ước tính phục vụ demo | G32: Đại diện cơ cấu dân số | I32: Ước tính tổng tỷ lệ trẻ em và người cao tuổi; cần thay bằng dữ liệu điều tra chi tiết khi có. | J32: https://vietnam.unfpa.org/sites/default/files/pub-pdf/Results%20-%202019%20Population%20and%20Housing%20Census_full.pdf
A33: 28 | B33: Hải Phòng | C33: GRDP/người đại diện | D33: 173 | E33: triệu đồng/năm | F33: Ước tính phục vụ demo | G33: 2023-2024 đại diện | I33: Dùng làm proxy cho năng lực thích ứng kinh tế; không dùng như số liệu báo cáo chính thức. | J33: https://www.nso.gov.vn/wp-content/uploads/2025/06/NGTK-Cuc-TK-2024_BQ_PDF.pdf
A34: 29 | B34: Cần Thơ | C34: PM2.5 | D34: 30 | E34: µg/m³ | F34: Có nguồn + ước tính đại diện | G34: 2025 / đại diện | H34: 19 | I34: PM2.5 hiện tại: 19.0 µg/m³. Giá trị dùng chấm điểm là mức đại diện, tránh biến động theo từng giờ. Giá trị đại diện được ước tính từ dữ liệu trang và vị thế tương đối giữa các thành phố. | J34: https://www.iqair.com/air-quality/vietnam/can-tho-city/can-tho
A35: 30 | B35: Cần Thơ | C35: Nhiệt độ mùa nóng | D35: 35.5 | E35: °C | F35: Ước tính từ dữ liệu ngày hiện tại | G35: Mùa nóng đại diện | H35: 34 | I35: Nhiệt độ cao nhất hôm nay dùng làm tham khảo; mức chấm điểm được nâng về giá trị mùa nóng điển hình. | J35: https://www.iqair.com/air-quality/vietnam/can-tho-city/can-tho
A36: 31 | B36: Cần Thơ | C36: Tiếng ồn đô thị | D36: 68 | E36: dB | F36: Ước tính phục vụ demo | G36: Đại diện ban ngày | I36: Hà Nội và TP.HCM tham chiếu nghiên cứu tiếng ồn giao thông; thành phố khác ước tính theo quy mô giao thông. | J36: https://www.sciencedirect.com/science/article/abs/pii/S0003682X09002710
A37: 32 | B37: Cần Thơ | C37: Mật độ dân số | D37: 874 | E37: người/km² | F37: Số liệu thống kê | G37: 2023 | I37: CEIC dẫn nguồn Tổng cục Thống kê / National Statistics Office. | J37: https://www.ceicdata.com/en/vietnam/population-density-by-provinces/population-density-mr-can-tho
A38: 33 | B38: Cần Thơ | C38: Không gian xanh | D38: 4.5 | E38: m²/người | F38: Ước tính phục vụ demo | G38: 2025 / đại diện | I38: Hà Nội, TP.HCM và Đà Nẵng có số liệu công bố; Hải Phòng và Cần Thơ ước tính theo quy mô đô thị. | J38: https://vietnamnews.vn/society/1692989/urban-greenery-falls-short-despite-tree-planting-effort.html
A39: 34 | B39: Cần Thơ | C39: Nhóm dễ tổn thương | D39: 32 | E39: % | F39: Ước tính phục vụ demo | G39: Đại diện cơ cấu dân số | I39: Ước tính tổng tỷ lệ trẻ em và người cao tuổi; cần thay bằng dữ liệu điều tra chi tiết khi có. | J39: https://vietnam.unfpa.org/sites/default/files/pub-pdf/Results%20-%202019%20Population%20and%20Housing%20Census_full.pdf
A40: 35 | B40: Cần Thơ | C40: GRDP/người đại diện | D40: 96 | E40: triệu đồng/năm | F40: Ước tính phục vụ demo | G40: 2023-2024 đại diện | I40: Dùng làm proxy cho năng lực thích ứng kinh tế; không dùng như số liệu báo cáo chính thức. | J40: https://www.nso.gov.vn/wp-content/uploads/2025/06/NGTK-Cuc-TK-2024_BQ_PDF.pdf
A42: GỢI Ý KẾT NỐI API CHO DEVELOPER
A43: Dữ liệu | B43: Nhà cung cấp | C43: Trường cần lấy | D43: Tần suất gợi ý | E43: Cần API key? | F43: Endpoint mẫu | G43: Dùng ngay? | H43: Fallback | I43: Tài liệu | J43: Ghi chú
...

Sheet Thư viện khuyến nghị
A1: THƯ VIỆN KHUYẾN NGHỊ HEBI - PHIÊN BẢN ĐƠN GIẢN
A3: Hệ thống chỉ xác định tác nhân có đóng góp lớn nhất vào Điểm HEBI, sau đó trả về một khuyến nghị cố định tương ứng. Không chia cấp độ và không dùng AI.
A5: Tác nhân chính | B5: Khuyến nghị ngắn | C5: Hành động gợi ý 1 | D5: Hành động gợi ý 2 | E5: Giải thích cho người dùng
A6: PM2.5 | B6: Ưu tiên giảm phơi nhiễm và phát thải bụi mịn PM2.5. | C6: Tăng giám sát chất lượng không khí tại trường học, bệnh viện và khu dân cư đông đúc. | D6: Phát cảnh báo sức khỏe trong các ngày có nồng độ PM2.5 cao. | E6: PM2.5 là yếu tố đóng góp lớn nhất vào gánh nặng môi trường của thành phố.
A7: Nhiệt độ | B7: Ưu tiên giảm căng thẳng nhiệt tại các khu vực đô thị nóng. | C7: Tăng cây xanh, bóng râm và các điểm làm mát công cộng. | D7: Phát cảnh báo nắng nóng cho người lao động ngoài trời và nhóm dễ tổn thương. | E7: Nhiệt đô thị là yếu tố đóng góp lớn nhất vào gánh nặng môi trường của thành phố.
A8: Tiếng ồn | B8: Ưu tiên kiểm soát tiếng ồn giao thông và xây dựng. | C8: Theo dõi tiếng ồn tại các trục đường lớn, trường học và bệnh viện. | D8: Hạn chế còi xe và hoạt động gây ồn tại các khung giờ nhạy cảm. | E8: Tiếng ồn là yếu tố đóng góp lớn nhất vào gánh nặng môi trường của thành phố.
A9: Mật độ dân số | B9: Ưu tiên can thiệp tại các khu vực có mật độ dân số cao. | C9: Đặt thiết bị giám sát môi trường tại các khu dân cư đông đúc. | D9: Tập trung cảnh báo và nguồn lực vào nơi có số người bị ảnh hưởng lớn nhất. | E9: Mật độ dân số cao làm cùng một mức ô nhiễm ảnh hưởng đến nhiều người hơn.
A10: Thiếu không gian xanh | B10: Ưu tiên mở rộng và bảo vệ không gian xanh đô thị. | C10: Phát triển công viên nhỏ, hành lang cây xanh và cây xanh quanh trường học. | D10: Ưu tiên các khu dân cư đông đúc đang thiếu khả năng tiếp cận không gian xanh. | E10: Thiếu không gian xanh làm giảm khả năng thích ứng với nhiệt, ô nhiễm và tiếng ồn.
A11: Nhóm dễ tổn thương | B11: Ưu tiên bảo vệ trẻ em, người cao tuổi và người có vấn đề sức khỏe. | C11: Gửi cảnh báo môi trường qua trường học, bệnh viện và cơ sở cộng đồng. | D11: Ưu tiên giám sát tại các khu vực tập trung nhiều nhóm dễ tổn thương. | E11: Tỷ lệ nhóm dễ tổn thương cao làm tác động môi trường trở nên nghiêm trọng hơn.
A12: Rủi ro thu nhập | B12: Ưu tiên các biện pháp bảo vệ môi trường dễ tiếp cận và chi phí thấp. | C12: Tập trung đầu tư công vào các cộng đồng có khả năng tự thích ứng thấp. | D12: Cung cấp cảnh báo và dịch vụ bảo vệ sức khỏe miễn phí hoặc trợ giá. | E12: Khả năng thích ứng kinh tế thấp làm người dân khó tự bảo vệ trước áp lực môi trường.

Sheet Hướng dẫn developer
A1: HƯỚNG DẪN TRIỂN KHAI THƯ VIỆN KHUYẾN NGHỊ
A3: 1. LOGIC XỬ LÝ
A4: Bước 1 | B4: Hệ thống đã tính được mức đóng góp có trọng số của 7 yếu tố.
A5: Bước 2 | B5: Chọn yếu tố có mức đóng góp cao nhất làm Tác nhân chính.
A6: Bước 3 | B6: Dùng tên Tác nhân chính làm khóa tra cứu trong thư viện khuyến nghị.
A7: Bước 4 | B7: Trả về một khuyến nghị ngắn, hai hành động gợi ý và một đoạn giải thích.
A8: Bước 5 | B8: Nếu không tìm thấy khóa phù hợp, dùng nội dung mặc định: “Tiếp tục theo dõi dữ liệu và cập nhật khuyến nghị khi có thêm thông tin.”
A10: 2. CẤU TRÚC DỮ LIỆU ĐỀ XUẤT
A11: main_driver | B11: recommendation | C11: action_1 | D11: action_2 | E11: explanation
A12: PM2.5 | B12: Ưu tiên giảm phơi nhiễm và phát thải bụi mịn PM2.5. | C12: Tăng giám sát tại trường học và bệnh viện. | D12: Phát cảnh báo trong ngày ô nhiễm cao. | E12: PM2.5 là yếu tố đóng góp lớn nhất vào gánh nặng môi trường.
A14: 3. PSEUDOCODE (MÃ GIẢ)
A15: main_driver = get_main_driver(weighted_contributions) recommendation_library = { "PM2.5": {...}, "Nhiệt độ": {...}, "Tiếng ồn": {...}, "Mật độ dân số": {...}, "Thiếu không gian xanh": {...}, "Nhóm dễ tổn thương": {...}, "Rủi ro thu nhập": {...} } result = recommendation_library.get(main_driver, default_recommendation)
A27: 4. YÊU CẦU TRIỂN KHAI
A28: Yêu cầu 1 | B28: Tên khóa trong code phải giống chính xác với tên Tác nhân chính trong hệ thống.
A29: Yêu cầu 2 | B29: Nội dung khuyến nghị nên lưu trong JSON, CSV, database hoặc object riêng, không hard-code trực tiếp trong giao diện.
A30: Yêu cầu 3 | B30: Developer cần tạo một khuyến nghị mặc định để tránh lỗi khi khóa không khớp.
A31: Yêu cầu 4 | B31: Admin hoặc chủ dự án có thể sửa nội dung thư viện mà không cần thay đổi công thức tính HEBI.
A32: Yêu cầu 5 | B32: Phiên bản MVP chỉ hiển thị một khuyến nghị chính và tối đa hai hành động gợi ý.
